<?xml version="1.0" ?>
<!-- =================================================================================== -->
<!-- |    This document was autogenerated by xacro from testbot.xacro                  | -->
<!-- |    EDITING THIS FILE BY HAND IS NOT RECOMMENDED                                 | -->
<!-- =================================================================================== -->
<robot name="four_wheel_bot">
  <!-- Define material colors -->
  <material name="blue">
    <color rgba="0 0 0.8 1"/>
  </material>
  <material name="red">
    <color rgba="0.8 0 0 1"/>
  </material>
  <material name="green">
    <color rgba="0 0.8 0 1"/>
  </material>
  <material name="gray">
    <color rgba="0.5 0.5 0.5 1"/>
  </material>
  <material name="black">
    <color rgba="0 0 0 1"/>
  </material>
  <!-- Camera holder height, matches base_height + 0.03 -->
  <!-- Base Footprint Link -->
  <link name="base_footprint">
  </link>
  <!-- Base Link (Chassis) -->
  <link name="base_link">
    <visual>
      <geometry>
        <box size="0.4 0.3 0.15"/>
      </geometry>
      <material name="blue"/>
      <origin rpy="0 0 0" xyz="0 0 0.075"/>
    </visual>
    <collision>
      <geometry>
        <box size="0.4 0.3 0.15"/>
      </geometry>
      <origin rpy="0 0 0" xyz="0 0 0.075"/>
    </collision>
    <inertial>
      <mass value="5.0"/>
      <inertia ixx="0.1" ixy="0" ixz="0" iyy="0.1" iyz="0" izz="0.1"/>
      <origin xyz="0 0 0.075"/>
    </inertial>
  </link>
  <!-- Joint between base_footprint and base_link -->
  <joint name="base_footprint_joint" type="fixed">
    <parent link="base_footprint"/>
    <child link="base_link"/>
    <origin rpy="0 0 0" xyz="0 0 0.05"/>
  </joint>
  <link name="front_left_wheel">
    <visual>
      <geometry>
        <cylinder length="0.02" radius="0.05"/>
      </geometry>
      <material name="black"/>
      <origin rpy="1.5707963267948966 0 0" xyz="0 0 0"/>
    </visual>
    <collision>
      <geometry>
        <cylinder length="0.02" radius="0.05"/>
      </geometry>
      <origin rpy="1.5707963267948966 0 0" xyz="0 0 0"/>
      <surface>
        <friction>
          <ode>
            <mu>1.0</mu>
            <mu2>1.0</mu2>
          </ode>
        </friction>
      </surface>
    </collision>
    <inertial>
      <mass value="0.5"/>
      <inertia ixx="0.005" ixy="0" ixz="0" iyy="0.005" iyz="0" izz="0.005"/>
    </inertial>
  </link>
  <joint name="front_left_wheel_joint" type="continuous">
    <parent link="base_link"/>
    <child link="front_left_wheel"/>
    <origin rpy="0 0 0" xyz="0.1 0.16 0"/>
    <axis xyz="0 1 0"/>
  </joint>
  <link name="front_right_wheel">
    <visual>
      <geometry>
        <cylinder length="0.02" radius="0.05"/>
      </geometry>
      <material name="black"/>
      <origin rpy="1.5707963267948966 0 0" xyz="0 0 0"/>
    </visual>
    <collision>
      <geometry>
        <cylinder length="0.02" radius="0.05"/>
      </geometry>
      <origin rpy="1.5707963267948966 0 0" xyz="0 0 0"/>
      <surface>
        <friction>
          <ode>
            <mu>1.0</mu>
            <mu2>1.0</mu2>
          </ode>
        </friction>
      </surface>
    </collision>
    <inertial>
      <mass value="0.5"/>
      <inertia ixx="0.005" ixy="0" ixz="0" iyy="0.005" iyz="0" izz="0.005"/>
    </inertial>
  </link>
  <joint name="front_right_wheel_joint" type="continuous">
    <parent link="base_link"/>
    <child link="front_right_wheel"/>
    <origin rpy="0 0 0" xyz="0.1 -0.16 0"/>
    <axis xyz="0 1 0"/>
  </joint>
  <link name="rear_left_wheel">
    <visual>
      <geometry>
        <cylinder length="0.02" radius="0.05"/>
      </geometry>
      <material name="black"/>
      <origin rpy="1.5707963267948966 0 0" xyz="0 0 0"/>
    </visual>
    <collision>
      <geometry>
        <cylinder length="0.02" radius="0.05"/>
      </geometry>
      <origin rpy="1.5707963267948966 0 0" xyz="0 0 0"/>
      <surface>
        <friction>
          <ode>
            <mu>1.0</mu>
            <mu2>1.0</mu2>
          </ode>
        </friction>
      </surface>
    </collision>
    <inertial>
      <mass value="0.5"/>
      <inertia ixx="0.005" ixy="0" ixz="0" iyy="0.005" iyz="0" izz="0.005"/>
    </inertial>
  </link>
  <joint name="rear_left_wheel_joint" type="continuous">
    <parent link="base_link"/>
    <child link="rear_left_wheel"/>
    <origin rpy="0 0 0" xyz="-0.1 0.16 0"/>
    <axis xyz="0 1 0"/>
  </joint>
  <link name="rear_right_wheel">
    <visual>
      <geometry>
        <cylinder length="0.02" radius="0.05"/>
      </geometry>
      <material name="black"/>
      <origin rpy="1.5707963267948966 0 0" xyz="0 0 0"/>
    </visual>
    <collision>
      <geometry>
        <cylinder length="0.02" radius="0.05"/>
      </geometry>
      <origin rpy="1.5707963267948966 0 0" xyz="0 0 0"/>
      <surface>
        <friction>
          <ode>
            <mu>1.0</mu>
            <mu2>1.0</mu2>
          </ode>
        </friction>
      </surface>
    </collision>
    <inertial>
      <mass value="0.5"/>
      <inertia ixx="0.005" ixy="0" ixz="0" iyy="0.005" iyz="0" izz="0.005"/>
    </inertial>
  </link>
  <joint name="rear_right_wheel_joint" type="continuous">
    <parent link="base_link"/>
    <child link="rear_right_wheel"/>
    <origin rpy="0 0 0" xyz="-0.1 -0.16 0"/>
    <axis xyz="0 1 0"/>
  </joint>
  <!-- LIDAR Holder -->
  <link name="lidar_holder">
    <visual>
      <geometry>
        <cylinder length="0.06" radius="0.02"/>
      </geometry>
      <material name="gray"/>
      <origin rpy="0 0 0" xyz="0 0 0.03"/>
    </visual>
    <collision>
      <geometry>
        <cylinder length="0.06" radius="0.02"/>
      </geometry>
      <origin rpy="0 0 0" xyz="0 0 0.03"/>
    </collision>
    <inertial>
      <mass value="0.2"/>
      <inertia ixx="0.001" ixy="0" ixz="0" iyy="0.001" iyz="0" izz="0.001"/>
    </inertial>
  </link>
  <joint name="lidar_holder_joint" type="fixed">
    <parent link="base_link"/>
    <child link="lidar_holder"/>
    <origin rpy="0 0 0" xyz="0 0 0.15"/>
  </joint>
  <!-- LIDAR -->
  <link name="lidar_link">
    <visual>
      <geometry>
        <cylinder length="0.06" radius="0.05"/>
      </geometry>
      <material name="red"/>
      <origin rpy="0 0 0" xyz="0 0 0.03"/>
    </visual>
    <collision>
      <geometry>
        <cylinder length="0.06" radius="0.05"/>
      </geometry>
      <origin rpy="0 0 0" xyz="0 0 0.03"/>
    </collision>
    <inertial>
      <mass value="0.3"/>
      <inertia ixx="0.0015" ixy="0" ixz="0" iyy="0.0015" iyz="0" izz="0.0015"/>
    </inertial>
  </link>
  <joint name="lidar_joint" type="fixed">
    <parent link="lidar_holder"/>
    <child link="lidar_link"/>
    <origin rpy="0 0 0" xyz="0 0 0.06"/>
  </joint>
  <!-- Camera Holder -->
  <link name="camera_holder">
    <visual>
      <geometry>
        <cylinder length="0.015" radius="0.02"/>
      </geometry>
      <material name="gray"/>
      <origin rpy="0 0 0" xyz="0 0 0.0075"/>
    </visual>
    <collision>
      <geometry>
        <cylinder length="0.015" radius="0.02"/>
      </geometry>
      <origin rpy="0 0 0" xyz="0 0 0.0075"/>
    </collision>
    <inertial>
      <mass value="0.2"/>
      <inertia ixx="0.001" ixy="0" ixz="0" iyy="0.001" iyz="0" izz="0.001"/>
    </inertial>
  </link>
  <joint name="camera_holder_joint" type="fixed">
    <parent link="base_link"/>
    <child link="camera_holder"/>
    <origin rpy="0 0 0" xyz="0.15000000000000002 0 0.15"/>
  </joint>
  <!-- Camera Frame -->
  <link name="camera_frame">
    <visual>
      <geometry>
        <box size="0.06 0.06 0.02"/>
      </geometry>
      <material name="gray"/>
      <origin rpy="0 0 0" xyz="0 0 0"/>
    </visual>
    <collision>
      <geometry>
        <box size="0.06 0.06 0.02"/>
      </geometry>
      <origin rpy="0 0 0" xyz="0 0 0"/>
    </collision>
    <inertial>
      <mass value="0.1"/>
      <inertia ixx="0.0005" ixy="0" ixz="0" iyy="0.0005" iyz="0" izz="0.0005"/>
    </inertial>
  </link>
  <joint name="camera_frame_joint" type="fixed">
    <parent link="camera_holder"/>
    <child link="camera_frame"/>
    <origin rpy="0 0 0" xyz="0 0 0.015"/>
  </joint>
  <!-- Camera -->
  <link name="camera_link">
    <visual>
      <geometry>
        <box size="0.04 0.05 0.03"/>
      </geometry>
      <material name="green"/>
      <origin rpy="0 0 0" xyz="0.02 0 0"/>
    </visual>
    <collision>
      <geometry>
        <box size="0.04 0.05 0.03"/>
      </geometry>
      <origin rpy="0 0 0" xyz="0.02 0 0"/>
    </collision>
    <inertial>
      <mass value="0.2"/>
      <inertia ixx="0.001" ixy="0" ixz="0" iyy="0.001" iyz="0" izz="0.001"/>
    </inertial>
  </link>
  <joint name="camera_joint" type="fixed">
    <parent link="camera_frame"/>
    <child link="camera_link"/>
    <origin rpy="0 0 0" xyz="0.03 0 0"/>
  </joint>
  <!-- IMU -->
  <link name="imu_link">
    <visual>
      <geometry>
        <box size="0.04 0.04 0.02"/>
      </geometry>
      <material name="black"/>
      <origin rpy="0 0 0" xyz="0 0 0"/>
    </visual>
    <collision>
      <geometry>
        <box size="0.04 0.04 0.02"/>
      </geometry>
      <origin rpy="0 0 0" xyz="0 0 0"/>
    </collision>
    <inertial>
      <mass value="0.1"/>
      <inertia ixx="0.0005" ixy="0" ixz="0" iyy="0.0005" iyz="0" izz="0.0005"/>
    </inertial>
  </link>
  <joint name="imu_joint" type="fixed">
    <parent link="base_link"/>
    <child link="imu_link"/>
    <origin rpy="0 0 0" xyz="0 0 0.16999999999999998"/>
  </joint>
  <!-- Gazebo Plugins -->
  <!--Control ad gazebo control interface-->
  <ros2_control name="IgnitionSystem" type="system">
    <hardware>
      <plugin>gz_ros2_control/GazeboSimSystem</plugin>
    </hardware>
    <joint name="front_right_wheel_joint">
      <command_interface name="velocity">
        <param name="min">-20</param>
        <!-- 1.0 m/s / 0.05 m = 20 rad/s -->
        <param name="max">20</param>
      </command_interface>
      <state_interface name="position"/>
      <state_interface name="velocity"/>
    </joint>
    <joint name="rear_right_wheel_joint">
      <command_interface name="velocity">
        <param name="min">-20</param>
        <param name="max">20</param>
      </command_interface>
      <state_interface name="position"/>
      <state_interface name="velocity"/>
    </joint>
    <joint name="front_left_wheel_joint">
      <command_interface name="velocity">
        <param name="min">-20</param>
        <param name="max">20</param>
      </command_interface>
      <state_interface name="position"/>
      <state_interface name="velocity"/>
    </joint>
    <joint name="rear_left_wheel_joint">
      <command_interface name="velocity">
        <param name="min">-20</param>
        <param name="max">20</param>
      </command_interface>
      <state_interface name="position"/>
      <state_interface name="velocity"/>
    </joint>
  </ros2_control>
  <gazebo>
    <plugin filename="gz_ros2_control-system" name="gz_ros2_control::GazeboSimROS2ControlPlugin">
      <parameters>/home/jamih/botdev/install/testbot/share/testbot/config/4w_diff_drive_controller_velocity.yaml</parameters>
    </plugin>
  </gazebo>
  <gazebo reference="lidar_joint">
    <preserveFixedJoint>true</preserveFixedJoint>
  </gazebo>
  <gazebo reference="lidar_link">
    <sensor name="lidar" type="gpu_lidar">
      <ignition_frame_id>lidar_link</ignition_frame_id>
      <topic>/scan</topic>
      <always_on>true</always_on>
      <visualize>true</visualize>
      <update_rate>10</update_rate>
      <ray>
        <scan>
          <horizontal>
            <samples>360</samples>
            <resolution>1.0</resolution>
            <min_angle>-3.14</min_angle>
            <max_angle>3.14</max_angle>
          </horizontal>
        </scan>
        <range>
          <min>0.03</min>
          <max>10.0</max>
          <resolution>0.015</resolution>
        </range>
        <noise>
          <type>gaussian</type>
          <mean>0.0</mean>
          <stddev>0.01</stddev>
        </noise>
      </ray>
    </sensor>
  </gazebo>
  <!-- Camera Sensor Plugin -->
  <gazebo reference="camera_link">
    <sensor name="camera" type="camera">
      <camera>
        <horizontal_fov>1.047</horizontal_fov>
        <image>
          <width>320</width>
          <height>240</height>
          <format>R8G8B8</format>
        </image>
        <clip>
          <near>0.1</near>
          <far>20</far>
        </clip>
        <noise>
          <type>gaussian</type>
          <mean>0.0</mean>
          <stddev>0.007</stddev>
        </noise>
        <optical_frame_id>camera_frame</optical_frame_id>
        <camera_info_topic>camera_info</camera_info_topic>
      </camera>
      <always_on>1</always_on>
      <update_rate>10</update_rate>
      <visualize>true</visualize>
      <topic>/robot_cam</topic>
      <enable_metrics>true</enable_metrics>
    </sensor>
  </gazebo>
  <gazebo reference="imu_link">
    <sensor name="imu_sensor" type="imu">
      <ignition_frame_id>imu_link</ignition_frame_id>
      <plugin filename="ignition-gazebo-imu-system" name="ignition::gazebo::systems::Imu">
      </plugin>
      <topic>imu</topic>
      <always_on>true</always_on>
      <update_rate>100</update_rate>
      <visualize>true</visualize>
      <imu>
        <angular_velocity>
          <x>
            <noise type="gaussian">
              <mean>0.0</mean>
              <stddev>2e-4</stddev>
              <bias_mean>0.0000075</bias_mean>
              <bias_stddev>0.0000008</bias_stddev>
            </noise>
          </x>
          <y>
            <noise type="gaussian">
              <mean>0.0</mean>
              <stddev>2e-4</stddev>
              <bias_mean>0.0000075</bias_mean>
              <bias_stddev>0.0000008</bias_stddev>
            </noise>
          </y>
          <z>
            <noise type="gaussian">
              <mean>0.0</mean>
              <stddev>2e-4</stddev>
              <bias_mean>0.0000075</bias_mean>
              <bias_stddev>0.0000008</bias_stddev>
            </noise>
          </z>
        </angular_velocity>
        <linear_acceleration>
          <x>
            <noise type="gaussian">
              <mean>0.0</mean>
              <stddev>1.7e-2</stddev>
              <bias_mean>0.1</bias_mean>
              <bias_stddev>0.001</bias_stddev>
            </noise>
          </x>
          <y>
            <noise type="gaussian">
              <mean>0.0</mean>
              <stddev>1.7e-2</stddev>
              <bias_mean>0.1</bias_mean>
              <bias_stddev>0.001</bias_stddev>
            </noise>
          </y>
          <z>
            <noise type="gaussian">
              <mean>0.0</mean>
              <stddev>1.7e-2</stddev>
              <bias_mean>0.1</bias_mean>
              <bias_stddev>0.001</bias_stddev>
            </noise>
          </z>
        </linear_acceleration>
      </imu>
    </sensor>
  </gazebo>
</robot>
